<?xml version="1.0"?>
<robot name="cr16_robot" xmlns:xacro="http://ros.org/wiki/xacro">
  <link name="dummy_link"/>
  <link
    name="base_link">
    <inertial>
      <origin
        xyz="-0.0017434 -4.7187E-06 0.032774"
        rpy="0 0 0" />
      <mass
        value="1.8265" />
      <inertia
        ixx="0.0041731"
        ixy="5.9313E-07"
        ixz="2.5199E-05"
        iyy="0.0043128"
        iyz="-5.4485E-07"
        izz="0.0067702" />
    </inertial>
    <visual>
      <origin
        xyz="0 0 0"
        rpy="0 0 0" />
      <geometry>
        <mesh
          filename="package://dobot_description/meshes/cr16/base_link.STL"  />
      </geometry>
      <material
        name="">
        <color
          rgba="1 1 1 1" />
      </material>
    </visual>
    <collision>
      <origin
        xyz="0 0 0"
        rpy="0 0 0" />
      <geometry>
        <mesh
          filename="package://dobot_description/meshes/cr16/base_link.STL"/>
      </geometry>
    </collision>
  </link>
  <link  name="world"/>
<joint name="world_joint" type="fixed">
    <parent link="world" />
    <child  link="dummy_link" />
  </joint>

  <joint name="dummy_joint" type="fixed">
    <parent link="dummy_link" />
    <child  link="base_link" />
  </joint>
  <link
    name="Link1">
    <inertial>
      <origin
        xyz="-1.6641E-06 -0.010819 0.0028389"
        rpy="0 0 0" />
      <mass
        value="4.1649" />
      <inertia
        ixx="0.020714"
        ixy="-1.9337E-07"
        ixz="1.6016E-07"
        iyy="0.018824"
        iyz="-9.6732E-05"
        izz="0.014575" />
    </inertial>
    <visual>
      <origin
        xyz="0 0 0"
        rpy="0 0 0" />
      <geometry>
        <mesh
          filename="package://dobot_description/meshes/cr16/Link1.STL" />
      </geometry>
      <material
        name="">
        <color
          rgba="1 1 1 1" />
      </material>
    </visual>
    <collision>
      <origin
        xyz="0 0 0"
        rpy="0 0 0" />
      <geometry>
        <mesh
          filename="package://dobot_description/meshes/cr16/Link1.STL" />
      </geometry>
    </collision>
  </link>
  <joint
    name="joint1"
    type="revolute">
    <origin
      xyz="0 0 0.1765"
      rpy="0 0 0" />
    <parent
      link="base_link" />
    <child
      link="Link1" />
    <axis
      xyz="0 0 1" />
    <limit
      lower="-3.14"
      upper="3.14"
      effort="300"
      velocity="100" />
  </joint>
  <link
    name="Link2">
    <inertial>
      <origin
        xyz="-0.20512 -3.1886E-08 0.19538"
        rpy="0 0 0" />
      <mass
        value="10.222" />
      <inertia
        ixx="0.031498"
        ixy="-8.7366E-08"
        ixz="-0.00021952"
        iyy="0.06945"
        iyz="-1.4472E-07"
        izz="0.062387" />
    </inertial>
    <visual>
      <origin
        xyz="0 0 0"
        rpy="0 0 0" />
      <geometry>
        <mesh
          filename="package://dobot_description/meshes/cr16/Link2.STL"  />
      </geometry>
      <material
        name="">
        <color
          rgba="1 1 1 1" />
      </material>
    </visual>
    <collision>
      <origin
        xyz="0 0 0"
        rpy="0 0 0" />
      <geometry>
        <mesh
          filename="package://dobot_description/meshes/cr16/Link2.STL" />
      </geometry>
    </collision>
  </link>
  <joint
    name="joint2"
    type="revolute">
    <origin
      xyz="0 0 0"
      rpy="1.5708 1.5708 0" />
    <parent
      link="Link1" />
    <child
      link="Link2" />
    <axis
      xyz="0 0 1" />
    <limit
      lower="-3.14"
      upper="3.14"
      effort="300"
      velocity="100" />
  </joint>
  <link
    name="Link3">
    <inertial>
      <origin
        xyz="-0.170200593728399 2.11088122753169E-07 0.0611734146139162"
        rpy="0 0 0" />
      <mass
        value="3.75359417381617" />
      <inertia
        ixx="0.00603810286245228"
        ixy="-6.36208384653473E-08"
        ixz="-5.72052164068317E-05"
        iyy="0.0119444184036258"
        iyz="6.47950646898604E-08"
        izz="0.0107481567947292" />
    </inertial>
    <visual>
      <origin
        xyz="0 0 0"
        rpy="0 0 0" />
      <geometry>
        <mesh
          filename="package://dobot_description/meshes/cr16/Link3.STL" />
      </geometry>
      <material
        name="">
        <color
          rgba="1 1 1 1" />
      </material>
    </visual>
    <collision>
      <origin
        xyz="0 0 0"
        rpy="0 0 0" />
      <geometry>
        <mesh
          filename="package://dobot_description/meshes/cr16/Link3.STL" />
      </geometry>
    </collision>
  </link>
  <joint
    name="joint3"
    type="revolute">
    <origin
      xyz="-0.512 0 0"
      rpy="0 0 0" />
    <parent
      link="Link2" />
    <child
      link="Link3" />
    <axis
      xyz="0 0 1" />
    <limit
      lower="-2.86"
      upper="2.86"
      effort="300"
      velocity="100" />
  </joint>
  <link
    name="Link4">
    <inertial>
      <origin
        xyz="-2.51136414011728E-07 0.00798725336224493 -0.00589074250591318"
        rpy="0 0 0" />
      <mass
        value="1.16884301529359" />
      <inertia
        ixx="0.00292614958206067"
        ixy="8.13393336360205E-09"
        ixz="-8.19039910228418E-09"
        iyy="0.00150053008994198"
        iyz="-5.44925430410846E-05"
        izz="0.00273274970331529" />
    </inertial>
    <visual>
      <origin
        xyz="0 0 0"
        rpy="0 0 0" />
      <geometry>
        <mesh
          filename="package://dobot_description/meshes/cr16/Link4.STL" />
      </geometry>
      <material
        name="">
        <color
          rgba="1 1 1 1" />
      </material>
    </visual>
    <collision>
      <origin
        xyz="0 0 0"
        rpy="0 0 0" />
      <geometry>
        <mesh
          filename="package://dobot_description/meshes/cr16/Link4.STL" />
      </geometry>
    </collision>
  </link>
  <joint
    name="joint4"
    type="revolute">
    <origin
      xyz="-0.363 0 0.191"
      rpy="0 0 -1.5708" />
    <parent
      link="Link3" />
    <child
      link="Link4" />
    <axis
      xyz="0 0 1" />
    <limit
      lower="-3.14"
      upper="3.14"
      effort="300"
      velocity="100" />
  </joint>
  <link
    name="Link5">
    <inertial>
      <origin
        xyz="5.95030917189652E-07 -0.0145467824834555 -0.00454892377987748"
        rpy="0 0 0" />
      <mass
        value="1.22302770181629" />
      <inertia
        ixx="0.00337903895296555"
        ixy="3.44280377037815E-08"
        ixz="-6.93979063565381E-09"
        iyy="0.001492552393115"
        iyz="8.41874314256677E-05"
        izz="0.00323298846154308" />
    </inertial>
    <visual>
      <origin
        xyz="0 0 0"
        rpy="0 0 0" />
      <geometry>
        <mesh
          filename="package://dobot_description/meshes/cr16/Link5.STL" />
      </geometry>
      <material
        name="">
        <color
          rgba="1 1 1 1" />
      </material>
    </visual>
    <collision>
      <origin
        xyz="0 0 0"
        rpy="0 0 0" />
      <geometry>
        <mesh
          filename="package://dobot_description/meshes/cr16/Link5.STL" />
      </geometry>
    </collision>
  </link>
  <joint
    name="joint5"
    type="revolute">
    <origin
      xyz="0 -0.125 0"
      rpy="1.5708 0 0" />
    <parent
      link="Link4" />
    <child
      link="Link5" />
    <axis
      xyz="0 0 1" />
    <limit
      lower="-3.14"
      upper="3.14"
      effort="300"
      velocity="100" />
  </joint>
  <link
    name="Link6">
    <inertial>
      <origin
        xyz="1.26507355792134E-07 2.29654719696715E-05 -0.0205297779952012"
        rpy="0 0 0" />
      <mass
        value="0.205439539605232" />
      <inertia
        ixx="0.000110115415603791"
        ixy="-2.45819491561588E-13"
        ixz="-2.41984454633386E-13"
        iyy="0.000110662465683831"
        iyz="3.68892612776179E-08"
        izz="0.000205184285911954" />
    </inertial>
    <visual>
      <origin
        xyz="0 0 0"
        rpy="0 0 0" />
      <geometry>
        <mesh
          filename="package://dobot_description/meshes/cr16/Link6.STL"/>
      </geometry>
      <material
        name="">
        <color
          rgba="1 1 1 1" />
      </material>
    </visual>
    <collision>
      <origin
        xyz="0 0 0"
        rpy="0 0 0" />
      <geometry>
        <mesh
          filename="package://dobot_description/meshes/cr16/Link6.STL" />
      </geometry>
    </collision>
  </link>
  <joint
    name="joint6"
    type="revolute">
    <origin
      xyz="0 0.1084 0"
      rpy="-1.5708 0 0" />
    <parent
      link="Link5" />
    <child
      link="Link6" />
    <axis
      xyz="0 0 1" />
    <limit
      lower="-6.28"
      upper="6.28"
      effort="300"
      velocity="100" />
  </joint>

 <xacro:macro name="cr16_transmission" params="joint_name">
     <transmission name="${joint_name}_trans">
       <type>transmission_interface/SimpleTransmission</type>
       <joint name="${joint_name}">
         <!--<hardwareInterface>hardware_interface/PositionJointInterface</hardwareInterface>-->
         <hardwareInterface>hardware_interface/PositionJointInterface</hardwareInterface>
       </joint>
       <actuator name="${joint_name}_motor">
         <mechanicalReduction>1</mechanicalReduction>
       </actuator>
     </transmission>
 </xacro:macro>

 <xacro:cr16_transmission joint_name="joint1"/>
 <xacro:cr16_transmission joint_name="joint2"/>
 <xacro:cr16_transmission joint_name="joint3"/>
 <xacro:cr16_transmission joint_name="joint4"/>
 <xacro:cr16_transmission joint_name="joint5"/>
 <xacro:cr16_transmission joint_name="joint6"/>
 <!-- ros_control plugin -->
 <gazebo>
     <plugin name="gazebo_ros_control" filename="libgazebo_ros_control.so">
         <robotNamespace>/cr16_robot</robotNamespace>
     </plugin>
 </gazebo>



</robot>
