<?xml version="1.0" encoding="utf-8"?>
<!-- This URDF was automatically created by SolidWorks to URDF Exporter! Originally created by Stephen Brawner (brawner@gmail.com) 
     Commit Version: 1.6.0-1-g15f4949  Build Version: 1.6.7594.29634
     For more information, please see http://wiki.ros.org/sw_urdf_exporter -->
<robot
  name="nova5_robot">
  <link name="dummy_link"/>
  <link
    name="base_link">
    <inertial>
      <origin
        xyz="6.56698714338847E-06 2.73052159273858E-06 0.0698223124889706"
        rpy="0 0 0" />
      <mass
        value="1.3106443915978" />
      <inertia
        ixx="0.00308109148952278"
        ixy="-4.0369958400766E-08"
        ixz="5.2607663395944E-07"
        iyy="0.00309758743296662"
        iyz="-6.37484696538659E-09"
        izz="0.00232835367593981" />
    </inertial>
    <visual>
      <origin
        xyz="0 0 0"
        rpy="0 0 0" />
      <geometry>
        <mesh
          filename="package://dobot_description/meshes/nova5/base_link.STL" />
      </geometry>
      <material
        name="">
        <color
          rgba="0.792156862745098 0.819607843137255 0.933333333333333 1" />
      </material>
    </visual>
    <collision>
      <origin
        xyz="0 0 0"
        rpy="0 0 0" />
      <geometry>
        <mesh
          filename="package://dobot_description/meshes/nova5/base_link.STL" />
      </geometry>
    </collision>
  </link>
  <joint
    name="dummy_joint"
    type="fixed">
    <parent
      link="dummy_link" />
    <child
      link="base_link" />
  </joint>
  <link
    name="Link1">
    <inertial>
      <origin
        xyz="9.18642704220017E-06 -0.021770784235076 -0.0261833991373472"
        rpy="0 0 0" />
      <mass
        value="1.08090940330212" />
      <inertia
        ixx="0.00265963193119309"
        ixy="1.85196348994647E-07"
        ixz="-3.27720040926316E-07"
        iyy="0.00247342331575097"
        iyz="0.000661331129337329"
        izz="0.00164737186015792" />
    </inertial>
    <visual>
      <origin
        xyz="0 0 0"
        rpy="0 0 0" />
      <geometry>
        <mesh
          filename="package://dobot_description/meshes/nova5/Link1.STL" />
      </geometry>
      <material
        name="">
        <color
          rgba="0.792156862745098 0.819607843137255 0.933333333333333 1" />
      </material>
    </visual>
    <collision>
      <origin
        xyz="0 0 0"
        rpy="0 0 0" />
      <geometry>
        <mesh
          filename="package://dobot_description/meshes/nova5/Link1.STL" />
      </geometry>
    </collision>
  </link>
  <joint
    name="joint1"
    type="revolute">
    <origin
      xyz="0 0 0.240000000000178"
      rpy="0 0 0" />
    <parent
      link="base_link" />
    <child
      link="Link1" />
    <axis
      xyz="0 0 0.999999999999855" />
    <limit
      lower="-6.28"
      upper="6.28"
      effort="0"
      velocity="0" />
  </joint>
  <link
    name="Link2">
    <inertial>
      <origin
        xyz="-0.19933810729628 -0.00696463483971123 0.109208661556353"
        rpy="0 0 0" />
      <mass
        value="2.54585370113969" />
      <inertia
        ixx="0.00285193319464959"
        ixy="-0.00212784400881843"
        ixz="-0.00109906472415148"
        iyy="0.0636767872390402"
        iyz="-3.83872488712299E-05"
        izz="0.0643005121111712" />
    </inertial>
    <visual>
      <origin
        xyz="0 0 0"
        rpy="0 0 0" />
      <geometry>
        <mesh
          filename="package://dobot_description/meshes/nova5/Link2.STL" />
      </geometry>
      <material
        name="">
        <color
          rgba="0.792156862745098 0.819607843137255 0.933333333333333 1" />
      </material>
    </visual>
    <collision>
      <origin
        xyz="0 0 0"
        rpy="0 0 0" />
      <geometry>
        <mesh
          filename="package://dobot_description/meshes/nova5/Link2.STL" />
      </geometry>
    </collision>
  </link>
  <joint
    name="joint2"
    type="revolute">
    <origin
      xyz="0 0 0"
      rpy="-1.57080287682252 1.53586622836832 3.14159265358979" />
    <parent
      link="Link1" />
    <child
      link="Link2" />
    <axis
      xyz="0 0 1" />
    <limit
      lower="-3.14"
      upper="3.14"
      effort="0"
      velocity="0" />
  </joint>
  <link
    name="Link3">
    <inertial>
      <origin
        xyz="-0.152357289724291 -0.0053571688729055 0.0198991511385547"
        rpy="0 0 0" />
      <mass
        value="1.40745649848125" />
      <inertia
        ixx="0.00100801309674517"
        ixy="-0.00077546601599374"
        ixz="4.43267247578911E-05"
        iyy="0.0231741793950995"
        iyz="1.31338010910521E-06"
        izz="0.02359962285525" />
    </inertial>
    <visual>
      <origin
        xyz="0 0 0"
        rpy="0 0 0" />
      <geometry>
        <mesh
          filename="package://dobot_description/meshes/nova5/Link3.STL" />
      </geometry>
      <material
        name="">
        <color
          rgba="0.792156862745098 0.819607843137255 0.933333333333333 1" />
      </material>
    </visual>
    <collision>
      <origin
        xyz="0 0 0"
        rpy="0 0 0" />
      <geometry>
        <mesh
          filename="package://dobot_description/meshes/nova5/Link3.STL" />
      </geometry>
    </collision>
  </link>
  <joint
    name="joint3"
    type="revolute">
    <origin
      xyz="-0.399756009268664 -0.0139690033141953 0"
      rpy="0 0 0" />
    <parent
      link="Link2" />
    <child
      link="Link3" />
    <axis
      xyz="0 0 1" />
    <limit
      lower="-2.79"
      upper="2.79"
      effort="0"
      velocity="0" />
  </joint>
  <link
    name="Link4">
    <inertial>
      <origin
        xyz="-6.37112093033953E-06 -0.0227590499933018 -0.0202381689250349"
        rpy="0 0 0" />
      <mass
        value="0.439666284541787" />
      <inertia
        ixx="0.000634738696193051"
        ixy="1.33529119545257E-08"
        ixz="2.91412587537874E-08"
        iyy="0.00045014395177395"
        iyz="0.000210919680187578"
        izz="0.000480311391216564" />
    </inertial>
    <visual>
      <origin
        xyz="0 0 0"
        rpy="0 0 0" />
      <geometry>
        <mesh
          filename="package://dobot_description/meshes/nova5/Link4.STL" />
      </geometry>
      <material
        name="">
        <color
          rgba="0.792156862745098 0.819607843137255 0.933333333333333 1" />
      </material>
    </visual>
    <collision>
      <origin
        xyz="0 0 0"
        rpy="0 0 0" />
      <geometry>
        <mesh
          filename="package://dobot_description/meshes/nova5/Link4.STL" />
      </geometry>
    </collision>
  </link>
  <joint
    name="joint4"
    type="revolute">
    <origin
      xyz="-0.329798707647103 -0.0115244277211674 0.134999532858734"
      rpy="0 0 -1.53586622840712" />
    <parent
      link="Link3" />
    <child
      link="Link4" />
    <axis
      xyz="0 0 1" />
    <limit
      lower="-6.28"
      upper="6.28"
      effort="0"
      velocity="0" />
  </joint>
  <link
    name="Link5">
    <inertial>
      <origin
        xyz="-1.27925890990664E-06 0.00190911597991161 -0.0076111865696753"
        rpy="0 0 0" />
      <mass
        value="0.574835130260071" />
      <inertia
        ixx="0.000663176880523558"
        ixy="1.30179448329138E-08"
        ixz="1.22670358756949E-08"
        iyy="0.000397520749670404"
        iyz="-0.00012026389265228"
        izz="0.000641156648195347" />
    </inertial>
    <visual>
      <origin
        xyz="0 0 0"
        rpy="0 0 0" />
      <geometry>
        <mesh
          filename="package://dobot_description/meshes/nova5/Link5.STL" />
      </geometry>
      <material
        name="">
        <color
          rgba="0.792156862745098 0.819607843137255 0.933333333333333 1" />
      </material>
    </visual>
    <collision>
      <origin
        xyz="0 0 0"
        rpy="0 0 0" />
      <geometry>
        <mesh
          filename="package://dobot_description/meshes/nova5/Link5.STL" />
      </geometry>
    </collision>
  </link>
  <joint
    name="joint5"
    type="revolute">
    <origin
      xyz="0 -0.12 0"
      rpy="1.5708 0 0" />
    <parent
      link="Link4" />
    <child
      link="Link5" />
    <axis
      xyz="0 0 1" />
    <limit
      lower="-6.28"
      upper="6.28"
      effort="0"
      velocity="0" />
  </joint>
  <link
    name="Link6">
    <inertial>
      <origin
        xyz="1.5476173180832E-06 0.000151598525687691 -0.0194592287865595"
        rpy="0 0 0" />
      <mass
        value="0.129679940383395" />
      <inertia
        ixx="5.02803124561327E-05"
        ixy="6.27222112028976E-11"
        ixz="3.5128727780266E-12"
        iyy="5.05400746124736E-05"
        iyz="5.0343678900728E-08"
        izz="7.7863015024978E-05" />
    </inertial>
    <visual>
      <origin
        xyz="0 0 0"
        rpy="0 0 0" />
      <geometry>
        <mesh
          filename="package://dobot_description/meshes/nova5/Link6.STL" />
      </geometry>
      <material
        name="">
        <color
          rgba="0.752941176470588 0.752941176470588 0.752941176470588 1" />
      </material>
    </visual>
    <collision>
      <origin
        xyz="0 0 0"
        rpy="0 0 0" />
      <geometry>
        <mesh
          filename="package://dobot_description/meshes/nova5/Link6.STL" />
      </geometry>
    </collision>
  </link>
  <joint
    name="joint6"
    type="revolute">
    <origin
      xyz="0 0.088328 0"
      rpy="-1.5708 0 0" />
    <parent
      link="Link5" />
    <child
      link="Link6" />
    <axis
      xyz="0 0 1" />
    <limit
      lower="-6.28"
      upper="6.28"
      effort="0"
      velocity="0" />
  </joint>
</robot>
